<?xml version="1.0"?>
<robot name="terabot" xmlns:xacro="http://www.ros.org/wiki/xacro"> 

  <!-- Import all common definitions -->
  <xacro:include filename="$(find terabot_description)/urdf/common.xacro" />


  <link name="base_link">
  </link>
  <joint name="base_joint" type="revolute">
    <origin xyz="0 0 ${(229/2)*BASE}"/>
    <axis xyz="0 0 1"/>
    <limit effort="1000.0" lower="${-170*(PI/180)}" upper="${170*(PI/180)}" velocity="0.5"/>
    <parent link="base_link"/>
    <child link="arm_base_link"/>
    <dynamics damping="0.001"/>
  </joint>

  <xacro:include filename="$(find terabot_description)/urdf/terabot.xacro" />
</robot>
